Workbook

Sheet metadata
A1: key: | C1: description
A2: gas | C2: gas that is being measured
A3: units: | B3: co2e | C3: volume of that gas in co2e
B4: (gas) | C4: if the gas is present, the total refernced on the SIT sheet is in terms of the volume of gas emitted, not the co2 equivalent
A5: sit_sheet | C5: sheet in the SIT to reference
A6: sit_row | C6: row in the SIT sheet storing the time series to match

Sheet sum_sheet
A1: subsector | B1: gas | C1: variable_field | D1: variables | E1: accounted | F1: sit_units | G1: sit_gas_measure | H1: sit_sheet | I1: sit_sections | J1: sit_subsections | K1: sit_categories | L1: sit_rows | M1: notes | N1: 1990 | O1: 1991 | P1: 1992 | Q1: 1993 | R1: 1994 | S1: 1995 | T1: 1996 | U1: 1997 | V1: 1998 | W1: 1999 | X1: 2000 | Y1: 2001 | Z1: 2002 | AA1: 2003 | AB1: 2004 | AC1: 2005 | AD1: 2006 | AE1: 2007 | AF1: 2008 | AG1: 2009 | AH1: 2010 | AI1: 2011 | AJ1: 2012 | AK1: 2013 | AL1: 2014 | AM1: 2015 | AN1: 2016 | AO1: 2017 | AP1: 2018 | AQ1: 2019 | AR1: 2020 | AS1: 2021 | AT1: 2022 | AU1: 2023 | AV1: 2024 | AW1: 2025 | AZ1: 2021:MTCO2e:factor | BA1: 2021:MTCO2e:value
A2: Agriculture | B2: ch4 | C2: emission_co2e_ch4_agrc_anaerobicdom_rice | D2: :math:\text{CH}_4 Emissions from Manure Management | E2: 1 | F2: MMT | G2: ch4 | H2: Agriculture | I2: Emissions by Gas (MMTCH4 or MMTN2O) | J2: Methane | K2: Rice Cultivation | L2: 35 | N2: 0.10734434 | O2: 0.10045067 | P2: 0.1221165 | Q2: 0.10438991 | R2: 0.1221165 | S2: 0.11226839 | T2: 0.1049808 | U2: 0.1148289 | V2: 0.1221165 | W2: 0.12132865 | X2: 0.094541805 | Y2: 0.1075413 | Z2: 0.10537472 | AA2: 0.088632942 | AB2: 0.1049808 | AC2: 0.1034051 | AD2: 0.067951922 | AE2: 0.074451671 | AF2: 0.091390411 | AG2: 0.091390411 | AH2: 0.10537472 | AI2: 0.082330155 | AJ2: 0.078193951 | AK2: 0.081345345 | AL2: 0.090996487 | AM2: 0.081739269 | AN2: 0.084299776 | AO2: 0.077800027 | AP2: 0.085875473 | AQ2: 0.05201375 | AR2: 0.09316307 | AS2: 0.081345345 | AT2: 0 | AU2: 0 | AV2: 0 | AW2: 0 | AZ2: 28 | BA2: =+AZ2*AS2 -> 2.2776697 | BC2: =+BA2+BA3 -> 2.3849737
A3: Agriculture | B3: ch4 | C3: emission_co2e_ch4_agrc_biomass_burning | D3: :math:\text{CH}_4 Emissions from Biomass Burning | E3: 1 | F3: MMT | G3: ch4 | H3: Agriculture | I3: Emissions by Gas (MMTCH4 or MMTN2O) | J3: Methane | K3: Burning of Agricultural Crop Waste | L3: 36 | N3: 0.0015555505 | O3: 0.0020815258 | P3: 0.0024065658 | Q3: 0.0023886054 | R3: 0.0025020291 | S3: 0.0027481731 | T3: 0.0028149625 | U3: 0.0031165779 | V3: 0.0034623954 | W3: 0.0040735058 | X3: 0.0040394385 | Y3: 0.0038958669 | Z3: 0.0038190801 | AA3: 0.0034697259 | AB3: 0.0029713343 | AC3: 0.002867873 | AD3: 0.0031997224 | AE3: 0.0035584724 | AF3: 0.0033495477 | AG3: 0.0037496202 | AH3: 0.0031756122 | AI3: 0.0032123134 | AJ3: 0.0039174261 | AK3: 0.0037820245 | AL3: 0.0033562129 | AM3: 0.0032637454 | AN3: 0.0032981598 | AO3: 0.0038947452 | AP3: 0.0041909434 | AQ3: 0.0034216034 | AR3: 0.0042626592 | AS3: 0.0038322882 | AT3: 0 | AU3: 0 | AV3: 0 | AW3: 0 | AZ3: 28 | BA3: =+AZ3*AS3 -> 0.10730407
A4: Agriculture | B4: n2o | C4: emission_co2e_n2o_agrc_biomass_burning | D4: :math:\text{N}_2\text{O} Emissions from Biomass Burning | E4: 1 | F4: MMT | G4: n2o | H4: Agriculture | I4: Emissions by Gas (MMTCH4 or MMTN2O) | J4: Nitrous Oxide | K4: Burning of Agricultural Crop Waste | L4: 40 | N4: 2.6948954e-05 | O4: 3.396973e-05 | P4: 3.947332e-05 | Q4: 3.8585334e-05 | R4: 4.0554653e-05 | S4: 4.424875e-05 | T4: 4.5717208e-05 | U4: 5.0332638e-05 | V4: 5.552604e-05 | W4: 6.5285569e-05 | X4: 6.5022538e-05 | Y4: 6.2754593e-05 | Z4: 6.1650642e-05 | AA4: 5.7203392e-05 | AB4: 4.7305532e-05 | AC4: 4.6428664e-05 | AD4: 5.1171939e-05 | AE4: 5.7670452e-05 | AF4: 5.5824837e-05 | AG4: 6.0831826e-05 | AH4: 5.1586672e-05 | AI4: 5.2968984e-05 | AJ4: 6.3953102e-05 | AK4: 6.2168487e-05 | AL4: 5.5274659e-05 | AM4: 5.2826425e-05 | AN4: 5.3079634e-05 | AO4: 6.2401022e-05 | AP4: 6.7080837e-05 | AQ4: 5.3867513e-05 | AR4: 6.808352e-05 | AS4: 6.128236e-05 | AT4: 0 | AU4: 0 | AV4: 0 | AW4: 0 | AZ4: 265 | BA4: =+AZ4*AS4 -> 0.016239825 | BC4: =+BA4+BA10 -> 0.53927484
A5: Agriculture | B5: co2 | C5: emission_co2e_co2_agrc_biomass_bevs_and_spices | D5: :math:\text{CO}_2 Emissions from Biomass Carbon Stock Changes | E5: 0 | F5: NA | G5: NA | H5: NA | I5: NA | J5: NA | K5: NA | L5: -1 | BA5: =+AZ5*AS5 -> 0
A6: Agriculture | B6: co2 | C6: emission_co2e_co2_agrc_biomass_fruits | D6: :math:\text{CO}_2 Emissions from Biomass Carbon Stock Changes | E6: 0 | F6: NA | G6: NA | H6: NA | I6: NA | J6: NA | K6: NA | L6: -1 | BA6: =+AZ6*AS6 -> 0
A7: Agriculture | B7: co2 | C7: emission_co2e_co2_agrc_biomass_nuts | D7: :math:\text{CO}_2 Emissions from Biomass Carbon Stock Changes | E7: 0 | F7: NA | G7: NA | H7: NA | I7: NA | J7: NA | K7: NA | L7: -1 | BA7: =+AZ7*AS7 -> 0
A8: Agriculture | B8: co2 | C8: emission_co2e_co2_agrc_biomass_other_woody_perennial | D8: :math:\text{CO}_2 Emissions from Biomass Carbon Stock Changes | E8: 0 | F8: NA | G8: NA | H8: NA | I8: NA | J8: NA | K8: NA | L8: -1 | BA8: =+AZ8*AS8 -> 0
A9: Agriculture | B9: co2 | C9: emission_co2e_co2_agrc_soil_carbon_organic_soils | D9: :math:\text{CO}_2 Emissions from Soil Carbon in Organic Soils | E9: 0 | F9: NA | G9: NA | H9: NA | I9: NA | J9: NA | K9: NA | L9: -1 | AX9: =+AX10+AS4 -> 1.9737783 | BA9: =+AZ9*AS9 -> 0
A10: Agriculture|Soil Management | B10: n2o | C10: emission_co2e_n2o_agrc_crop_residues | D10: :math:\text{N}_2\text{O} Emissions from Crop Residues | E10: 1 | F10: MT | G10: n2o | H10: Agriculture | I10: Nitrous Oxide Emissions from Agricultural Soil Management (Metric Tons N2O) | J10: Direct | K10: Crop Residues | L10: 46 | N10: 2140.6365 | O10: 1591.1561 | P10: 1816.2253 | Q10: 1643.0345 | R10: 1612.6049 | S10: 1381.0951 | T10: 1896.2746 | U10: 1750.2584 | V10: 1235.6221 | W10: 1530.1438 | X10: 1262.2422 | Y10: 1360.2882 | Z10: 1452.6446 | AA10: 1576.5255 | AB10: 1552.3857 | AC10: 1461.064 | AD10: 1324.4482 | AE10: 1782.8545 | AF10: 1714.4338 | AG10: 1738.6497 | AH10: 1860.3087 | AI10: 1781.2687 | AJ10: 2271.2345 | AK10: 2553.9787 | AL10: 2984.4072 | AM10: 2160.1016 | AN10: 2058.1772 | AO10: 2324.7285 | AP10: 2249.9325 | AQ10: 1480.9014 | AR10: 1943.4978 | AS10: 1973.717 | AT10: 0 | AU10: 0 | AV10: 0 | AW10: 0 | AX10: =+AS10/1000 -> 1.973717 | AZ10: =265/1000000 -> 0.000265 | BA10: =+AZ10*AS10 -> 0.52303501
A11: Carbon Capture and Sequestration | B11: ch4 | C11: emission_co2e_ch4_ccsq_direct_air_capture | D11: :math:\text{CH}_4 Emissions from CCSQ | E11: 0 | F11: NA | G11: NA | H11: NA | I11: NA | J11: NA | K11: NA | L11: -1 | BA11: =+AZ11*AS11 -> 0
A12: Carbon Capture and Sequestration | B12: co2 | C12: emission_co2e_co2_ccsq_direct_air_capture | D12: :math:\text{CO}_2 Emissions from CCSQ | E12: 0 | F12: NA | G12: NA | H12: NA | I12: NA | J12: NA | K12: NA | L12: -1 | BA12: =+AZ12*AS12 -> 0
A13: Carbon Capture and Sequestration | B13: n2o | C13: emission_co2e_n2o_ccsq_direct_air_capture | D13: :math:\text{N}_2\text{O} Emissions from CCSQ | E13: 0 | F13: NA | G13: NA | H13: NA | I13: NA | J13: NA | K13: NA | L13: -1 | BA13: =+AZ13*AS13 -> 0
A14: Energy Technology | B14: co2 | C14: emission_co2e_co2_entc_generation_pp_biogas|emission_co2e_co2_entc_generation_pp_biomass|emission_co2e_co2_entc_generation_pp_geothermal|emission_co2e_co2_entc_generation_pp_hydropower|emission_co2e_co2_entc_generation_pp_nuclear|emission_co2e_co2_entc_generation_pp_ocean|emission_co2e_co2_entc_generation_pp_solar|emission_co2e_co2_entc_generation_pp_waste_incineration|emission_co2e_co2_entc_generation_pp_wind | D14: NemoMod :math:\text{CO}_2 Emissions from Electricity Generation | E14: 1 | F14: MMT | G14: co2e | H14: CO2FFC | I14: Emissions (MMTCO2 Eq.) | J14: Electric Utilities | K14: Other | L14: 28 | N14: 0 | O14: 0 | P14: 0 | Q14: 0 | R14: 0 | S14: 0 | T14: 0 | U14: 0 | V14: 0 | W14: 0 | X14: 0 | Y14: 0 | Z14: 0 | AA14: 0 | AB14: 0 | AC14: 0 | AD14: 0 | AE14: 0 | AF14: 0 | AG14: 0 | AH14: 0 | AI14: 0 | AJ14: 0 | AK14: 0 | AL14: 0 | AM14: 0 | AN14: 0 | AO14: 0 | AP14: 0 | AQ14: 0 | AR14: 0 | AS14: 0 | AT14: 0 | AU14: 0 | AV14: 0 | AW14: 0 | AZ14: 1 | BA14: =+AZ14*AS14 -> 0 | BC14: =+BA14+BA15+BA16+BA17+BA18+BA19+BA20+BA21+BA22 -> 35.365523
A15: Energy Technology | B15: co2 | C15: emission_co2e_co2_entc_generation_pp_coal|emission_co2e_co2_entc_generation_pp_coal_ccs | D15: NemoMod :math:\text{CO}_2 Emissions from Electricity Generation | E15: 1 | F15: MMT | G15: co2e | H15: CO2FFC | I15: Emissions (MMTCO2 Eq.) | J15: Electric Utilities | K15: Coal | L15: 25 | N15: 18.34975 | O15: 19.423419 | P15: 20.242195 | Q15: 20.180057 | R15: 20.825336 | S15: 19.86951 | T15: 19.325535 | U15: 21.32277 | V15: 21.326637 | W15: 21.590696 | X15: 23.999887 | Y15: 22.681792 | Z15: 22.041419 | AA15: 23.414074 | AB15: 24.360017 | AC15: 24.090799 | AD15: 25.144979 | AE15: 23.683746 | AF15: 24.895938 | AG15: 24.081923 | AH15: 24.7601 | AI15: 25.664694 | AJ15: 22.6035 | AK15: 21.566142 | AL15: 19.772604 | AM15: 16.29956 | AN15: 13.040308 | AO15: 13.248607 | AP15: 12.805766 | AQ15: 8.3669597 | AR15: 4.3467994 | AS15: 8.7671403 | AT15: 0 | AU15: 0 | AV15: 0 | AW15: 0 | AZ15: 1 | BA15: =+AZ15*AS15 -> 8.7671403
A16: Energy Technology | B16: co2 | C16: emission_co2e_co2_entc_generation_pp_gas|emission_co2e_co2_entc_generation_pp_gas_ccs | D16: NemoMod :math:\text{CO}_2 Emissions from Electricity Generation | E16: 1 | F16: MMT | G16: co2e | H16: CO2FFC | I16: Emissions (MMTCO2 Eq.) | J16: Electric Utilities | K16: Natural Gas | L16: 27 | N16: 15.830166 | O16: 14.965601 | P16: 14.384787 | Q16: 13.524714 | R16: 15.458685 | S16: 17.953372 | T16: 14.042521 | U16: 15.326015 | V16: 17.675176 | W16: 17.752553 | X16: 16.729251 | Y16: 13.409598 | Z16: 17.649283 | AA16: 12.940872 | AB16: 13.393321 | AC16: 15.560754 | AD16: 10.777308 | AE16: 12.289939 | AF16: 12.943232 | AG16: 12.160236 | AH16: 14.692903 | AI16: 15.907857 | AJ16: 17.433066 | AK16: 14.495265 | AL16: 14.460649 | AM16: 18.648764 | AN16: 18.028772 | AO16: 15.193087 | AP16: 16.350366 | AQ16: 18.627116 | AR16: 19.334264 | AS16: 17.233476 | AT16: 0 | AU16: 0 | AV16: 0 | AW16: 0 | AZ16: 1 | BA16: =+AZ16*AS16 -> 17.233476
A17: Energy Technology | B17: co2 | C17: emission_co2e_co2_entc_generation_pp_oil | D17: NemoMod :math:\text{CO}_2 Emissions from Electricity Generation | E17: 1 | F17: MMT | G17: co2e | H17: CO2FFC | I17: Emissions (MMTCO2 Eq.) | J17: Electric Utilities | K17: Petroleum | L17: 26 | N17: 0.18089779 | O17: 0.038795899 | P17: 1.1893911 | Q17: 3.8014258 | R17: 2.5269755 | S17: 1.9023131 | T17: 2.0478675 | U17: 2.513537 | V17: 2.492945 | W17: 2.1102168 | X17: 2.1873281 | Y17: 3.4337184 | Z17: 2.0356469 | AA17: 2.9464161 | AB17: 3.4460166 | AC17: 3.4304583 | AD17: 2.1358556 | AE17: 2.363324 | AF17: 2.2393508 | AG17: 1.7153464 | AH17: 3.2582995 | AI17: 4.9029084 | AJ17: 3.1670704 | AK17: 4.9619162 | AL17: 5.2408644 | AM17: 4.4070674 | AN17: 5.1857247 | AO17: 5.0263259 | AP17: 4.7630533 | AQ17: 3.6731525 | AR17: 3.8665909 | AS17: 4.4027863 | AT17: 0 | AU17: 0 | AV17: 0 | AW17: 0 | AZ17: 1 | BA17: =+AZ17*AS17 -> 4.4027863
A18: Energy Technology | B18: co2 | C18: emission_co2e_co2_entc_processing_and_refinement_fp_ammonia_production | D18: NemoMod :math:\text{CO}_2 Emissions from Fuel Processing and Refinement | E18: 1 | F18: MT | G18: co2e | H18: IP | I18: Emissions (MTCO2 Eq.) | J18: Carbon Dioxide Emissions | K18: Aluminum Production, CO2 | L18: 9 | N18: 6118483.7 | O18: 6199141.4 | P18: 6479280.7 | Q18: 5966936.8 | R18: 6427645.8 | S18: 6055010.7 | T18: 6163277.1 | U18: 5875872.1 | V18: 5995087.6 | W18: 5481765.3 | X18: 4764037.5 | Y18: 3654103.2 | Z18: 3996107.2 | AA18: 3255297.3 | AB18: 3591722.8 | AC18: 3244324.1 | AD18: 3193927.9 | AE18: 3434106.3 | AF18: 3249900.9 | AG18: 3180329.4 | AH18: 3419343.3 | AI18: 3988084.5 | AJ18: 3087175.9 | AK18: 3167049.9 | AL18: 3200563.9 | AM18: 3282395.7 | AN18: 4348256.3 | AO18: 4640169 | AP18: 5014769.9 | AQ18: 5165855.4 | AR18: 5476635.5 | AS18: 4962120.2 | AT18: 0 | AU18: 0 | AV18: 0 | AW18: 0 | AZ18: =1/1000000 -> 1e-06 | BA18: =+AZ18*AS18 -> 4.9621202
A19: Energy Technology | B19: co2 | C19: emission_co2e_co2_entc_fuel_mining_and_extraction_me_coal | D19: NemoMod :math:\text{CO}_2 Emissions from Fuel Mining and Extraction | E19: 0 | F19: NA | G19: NA | H19: NA | I19: NA | J19: NA | K19: NA | L19: -1 | BA19: =+AZ19*AS19 -> 0
A20: Energy Technology | B20: co2 | C20: emission_co2e_co2_entc_fuel_mining_and_extraction_me_crude | D20: NemoMod :math:\text{CO}_2 Emissions from Fuel Mining and Extraction | E20: 0 | F20: NA | G20: NA | H20: NA | I20: NA | J20: NA | K20: NA | L20: -1 | BA20: =+AZ20*AS20 -> 0
A21: Energy Technology | B21: co2 | C21: emission_co2e_co2_entc_processing_and_refinement_fp_natural_gas | D21: NemoMod :math:\text{CO}_2 Emissions from Fuel Processing and Refinement | E21: 0 | F21: NA | G21: NA | H21: NA | I21: NA | J21: NA | K21: NA | L21: -1 | BA21: =+AZ21*AS21 -> 0
A22: Energy Technology | B22: co2 | C22: emission_co2e_co2_entc_processing_and_refinement_fp_petroleum_refinement | D22: NemoMod :math:\text{CO}_2 Emissions from Fuel Processing and Refinement | E22: 0 | F22: NA | G22: NA | H22: NA | I22: NA | J22: NA | K22: NA | L22: -1 | BA22: =+AZ22*AS22 -> 0
A23: Energy Technology | B23: n2o | C23: emission_co2e_n2o_entc_fuel_mining_and_extraction_me_coal | D23: NemoMod :math:\text{N}_2\text{O} Emissions from Fuel Mining and Extraction | E23: 0 | F23: NA | G23: NA | H23: NA | I23: NA | J23: NA | K23: NA | L23: -1 | BA23: =+AZ23*AS23 -> 0
A24: Energy Technology | B24: n2o | C24: emission_co2e_n2o_entc_fuel_mining_and_extraction_me_crude | D24: NemoMod :math:\text{N}_2\text{O} Emissions from Fuel Mining and Extraction | E24: 0 | F24: NA | G24: NA | H24: NA | I24: NA | J24: NA | K24: NA | L24: -1 | BA24: =+AZ24*AS24 -> 0
A25: Energy Technology | B25: n2o | C25: emission_co2e_n2o_entc_fuel_mining_and_extraction_me_natural_gas | D25: NemoMod :math:\text{N}_2\text{O} Emissions from Fuel Mining and Extraction | E25: 0 | F25: NA | G25: NA | H25: NA | I25: NA | J25: NA | K25: NA | L25: -1 | BA25: =+AZ25*AS25 -> 0
A26: Energy Technology | B26: n2o | C26: emission_co2e_n2o_entc_processing_and_refinement_fp_natural_gas | D26: NemoMod :math:\text{N}_2\text{O} Emissions from Fuel Processing and Refinement | E26: 0 | F26: NA | G26: NA | H26: NA | I26: NA | J26: NA | K26: NA | L26: -1 | BA26: =+AZ26*AS26 -> 0
A27: Energy Technology | B27: n2o | C27: emission_co2e_n2o_entc_processing_and_refinement_fp_petroleum_refinement | D27: NemoMod :math:\text{N}_2\text{O} Emissions from Fuel Processing and Refinement | E27: 0 | F27: NA | G27: NA | H27: NA | I27: NA | J27: NA | K27: NA | L27: -1 | BA27: =+AZ27*AS27 -> 0
A28: Energy Technology | B28: ch4 | C28: emission_co2e_ch4_entc_generation_pp_biogas|emission_co2e_ch4_entc_generation_pp_biomass|emission_co2e_ch4_entc_generation_pp_coal|emission_co2e_ch4_entc_generation_pp_coal_ccs|emission_co2e_ch4_entc_generation_pp_gas|emission_co2e_ch4_entc_generation_pp_gas_ccs|emission_co2e_ch4_entc_generation_pp_geothermal|emission_co2e_ch4_entc_generation_pp_hydropower|emission_co2e_ch4_entc_generation_pp_nuclear|emission_co2e_ch4_entc_generation_pp_ocean|emission_co2e_ch4_entc_generation_pp_oil|emission_co2e_ch4_entc_generation_pp_solar|emission_co2e_ch4_entc_generation_pp_waste_incineration|emission_co2e_ch4_entc_generation_pp_wind | D28: NemoMod :math:\text{CH}_4 Emissions from Electricity Generation | E28: 1 | F28: MMT | G28: co2e | H28: Stationary | I28: Emissions (MMTCO2 Eq.) | J28: Electric Utilities | K28: CH4 | L28: 15 | N28: 0.013526087 | O28: 0.013266356 | P28: 0.014162852 | Q28: 0.015973338 | R28: 0.016045411 | S28: 0.016438266 | T28: 0.014494261 | U28: 0.0161982 | V28: 0.017356602 | W28: 0.017084701 | X28: 0.017388613 | Y28: 0.016642662 | Z28: 0.017007399 | AA28: 0.016034756 | AB28: 0.017132251 | AC28: 0.018136363 | AD28: 0.014605147 | AE28: 0.015134805 | AF28: 0.01571446 | AG28: 0.014591564 | AH28: 0.017337188 | AI28: 0.019550821 | AJ28: 0.017982 | AK28: 0.017696659 | AL28: 0.017395193 | AM28: 0.017802954 | AN28: 0.017167455 | AO28: 0.015668179 | AP28: 0.015902423 | AQ28: 0.014853976 | AR28: 0.014183354 | AS28: 0.014862404 | AT28: 0 | AU28: 0 | AV28: 0 | AW28: 0 | AZ28: 1 | BA28: =+AZ28*AS28 -> 0.014862404
A29: Energy Technology | B29: n2o | C29: emission_co2e_n2o_entc_generation_pp_biogas|emission_co2e_n2o_entc_generation_pp_biomass|emission_co2e_n2o_entc_generation_pp_coal|emission_co2e_n2o_entc_generation_pp_coal_ccs|emission_co2e_n2o_entc_generation_pp_gas|emission_co2e_n2o_entc_generation_pp_gas_ccs|emission_co2e_n2o_entc_generation_pp_geothermal|emission_co2e_n2o_entc_generation_pp_hydropower|emission_co2e_n2o_entc_generation_pp_nuclear|emission_co2e_n2o_entc_generation_pp_ocean|emission_co2e_n2o_entc_generation_pp_oil|emission_co2e_n2o_entc_generation_pp_solar|emission_co2e_n2o_entc_generation_pp_waste_incineration|emission_co2e_n2o_entc_generation_pp_wind | D29: NemoMod :math:\text{N}_2\text{O} Emissions from Electricity Generation | E29: 1 | F29: MMT | G29: co2e | H29: Stationary | I29: Emissions (MMTCO2 Eq.) | J29: Electric Utilities | K29: N2O | L29: 14 | N29: 0.084145185 | O29: 0.087894707 | P29: 0.092800199 | Q29: 0.096713626 | R29: 0.098227934 | S29: 0.094153448 | T29: 0.090447802 | U29: 0.10029726 | V29: 0.10125401 | W29: 0.1015745 | X29: 0.11131736 | Y29: 0.10677399 | Z29: 0.10288198 | AA29: 0.10821405 | AB29: 0.11344696 | AC29: 0.11331739 | AD29: 0.11300486 | AE29: 0.10795353 | AF29: 0.11308632 | AG29: 0.10841283 | AH29: 0.11476805 | AI29: 0.12160713 | AJ29: 0.10679981 | AK29: 0.10400091 | AL29: 0.096991844 | AM29: 0.083072476 | AN29: 0.070439679 | AO29: 0.069733099 | AP29: 0.06800372 | AQ29: 0.048905784 | AR29: 0.03277684 | AS29: 0.050993979 | AT29: 0 | AU29: 0 | AV29: 0 | AW29: 0 | AZ29: 1 | BA29: =+AZ29*AS29 -> 0.050993979
A30: Energy Technology|Fugitive Emissions | B30: ch4 | C30: emission_co2e_ch4_entc_fuel_mining_and_extraction_me_coal|emission_co2e_ch4_fgtv_fuel_coal | D30: :math:\text{CH}_4 Fugitive Emissions|NemoMod :math:\text{CH}_4 Emissions from Fuel Mining and Extraction | E30: 1 | F30: MT | G30: ch4 | H30: Coal | I30: Emissions (MTCO2E) | J30: Coal Mining | L30: 23 | N30: 1234.4077 | O30: 1220.8471 | P30: 1255.3299 | Q30: 1214.2605 | R30: 1341.7307 | S30: 1440.9173 | T30: 1247.9684 | U30: 1373.5014 | V30: 1246.0312 | W30: 1144.1325 | X30: 1428.9064 | Y30: 1439.4202 | Z30: 1473.2726 | AA30: 1560.6811 | AB30: 1474.4268 | AC30: 1612.1543 | AD30: 1593.9652 | AE30: 1211.3879 | AF30: 1489.0549 | AG30: 1417.0567 | AH30: 1528.3029 | AI30: 1497.3684 | AJ30: 1538.604 | AK30: 1088.6387 | AL30: 1009.2573 | AM30: 1332.3266 | AN30: 1083.9448 | AO30: 805.33559 | AP30: 2497.5585 | AQ30: 691.57121 | AR30: 262.30196 | AS30: 116.23425 | AT30: 0 | AU30: 0 | AV30: 0 | AW30: 0 | AZ30: =28/1000000 -> 2.8e-05 | BA30: =+AZ30*AS30 -> 0.003254559 | BC30: =+BA30+BA31+BA32 -> 13.094104
A31: Energy Technology|Fugitive Emissions | B31: ch4 | C31: emission_co2e_ch4_entc_fuel_mining_and_extraction_me_crude|emission_co2e_ch4_entc_processing_and_refinement_fp_petroleum_refinement|emission_co2e_ch4_fgtv_fuel_oil | D31: :math:\text{CH}_4 Fugitive Emissions|NemoMod :math:\text{CH}_4 Emissions from Fuel Mining and Extraction|NemoMod :math:\text{CH}_4 Emissions from Fuel Processing and Refinement | E31: 1 | F31: MT | G31: ch4 | H31: Gas and Oil | I31: Emissions (MMTCO2 Eq.) | J31: Oil | L31: 23 | N31: 90478.679 | O31: 89903.821 | P31: 88502.27 | Q31: 89697.569 | R31: 84049.383 | S31: 89790.182 | T31: 100936.26 | U31: 103417.5 | V31: 104578.51 | W31: 96838.452 | X31: 86830.753 | Y31: 86829.878 | Z31: 78688.306 | AA31: 78076.828 | AB31: 75543.75 | AC31: 68396.062 | AD31: 71939.186 | AE31: 75188.253 | AF31: 73593.931 | AG31: 64633.277 | AH31: 62444.663 | AI31: 63655.555 | AJ31: 55859.743 | AK31: 61078.679 | AL31: 53559.127 | AM31: 47143.204 | AN31: 33590.296 | AO31: 39746.659 | AP31: 32298.584 | AQ31: 29210.513 | AR31: 23821.707 | AS31: 22610.56 | AT31: 0 | AU31: 0 | AV31: 0 | AW31: 0 | AZ31: =28/1000000 -> 2.8e-05 | BA31: =+AZ31*AS31 -> 0.63309567
A32: Energy Technology|Fugitive Emissions | B32: ch4 | C32: emission_co2e_ch4_entc_fuel_mining_and_extraction_me_natural_gas|emission_co2e_ch4_entc_processing_and_refinement_fp_natural_gas|emission_co2e_ch4_fgtv_fuel_natural_gas | D32: :math:\text{CH}_4 Fugitive Emissions|NemoMod :math:\text{CH}_4 Emissions from Fuel Mining and Extraction|NemoMod :math:\text{CH}_4 Emissions from Fuel Processing and Refinement | E32: 1 | F32: MT | G32: ch4 | H32: Gas and Oil | I32: Emissions by Gas (MTCH4) | J32: Natural Gas | L32: 19 | N32: 180543.41 | O32: 163857.83 | P32: 149712.96 | Q32: 175462.63 | R32: 148628.26 | S32: 165352.23 | T32: 181551.65 | U32: 177551.46 | V32: 218396.13 | W32: 198430.79 | X32: 186516 | Y32: 194074.5 | Z32: 202977 | AA32: 201065.93 | AB32: 246112.58 | AC32: 223607.06 | AD32: 207238.33 | AE32: 215381.15 | AF32: 228058.31 | AG32: 223868.2 | AH32: 523402.69 | AI32: 526211.98 | AJ32: 517804.83 | AK32: 508963.67 | AL32: 505075.25 | AM32: 501724.26 | AN32: 488874.69 | AO32: 480200.36 | AP32: 463434.43 | AQ32: 457583.82 | AR32: 443761.89 | AS32: 444919.77 | AT32: 270838.24 | AU32: 271113.7 | AV32: 0 | AW32: 0 | AZ32: =28/1000000 -> 2.8e-05 | BA32: =+AZ32*AS32 -> 12.457754
A33: Energy Technology|Fugitive Emissions | B33: co2 | C33: emission_co2e_co2_entc_fuel_mining_and_extraction_me_natural_gas|emission_co2e_co2_fgtv_fuel_natural_gas | D33: :math:\text{CO}_2 Fugitive Emissions|NemoMod :math:\text{CO}_2 Emissions from Fuel Mining and Extraction | E33: 1 | F33: MMT | G33: co2e | H33: Gas and Oil | I33: Emissions (MMTCO2 Eq.) | J33: Natural Gas | L33: 27 | N33: 0.026938547 | O33: 0.030454825 | P33: 0.031189952 | Q33: 0.032432963 | R33: 0.034580003 | S33: 0.034998556 | T33: 0.034753718 | U33: 0.0329468 | V33: 0.029365921 | W33: 0.026890403 | X33: 0.02553377 | Y33: 0.023262911 | Z33: 0.022013903 | AA33: 0.020275964 | AB33: 0.019231309 | AC33: 0.018264912 | AD33: 0.017620778 | AE33: 0.017508338 | AF33: 0.01795801 | AG33: 0.017010565 | AH33: 0.015522496 | AI33: 0.015344798 | AJ33: 0 | AK33: 0 | AL33: 0 | AM33: 0 | AN33: 0 | AO33: 0 | AP33: 0 | AQ33: 0 | AR33: 0 | AS33: 0 | AT33: 0 | AU33: 0 | AV33: 0 | AW33: 0 | AZ33: 1 | BA33: =+AZ33*AS33 -> 0
A34: Energy Technology|Industrial Energy | B34: co2 | C34: emission_co2e_co2_entc_processing_and_refinement_fp_hydrogen_electrolysis|emission_co2e_co2_entc_processing_and_refinement_fp_hydrogen_gasification|emission_co2e_co2_entc_processing_and_refinement_fp_hydrogen_reformation|emission_co2e_co2_entc_processing_and_refinement_fp_hydrogen_reformation_ccs|emission_co2e_co2_inen_agriculture_and_livestock|emission_co2e_co2_inen_cement|emission_co2e_co2_inen_chemicals|emission_co2e_co2_inen_electronics|emission_co2e_co2_inen_glass|emission_co2e_co2_inen_lime_and_carbonite|emission_co2e_co2_inen_metals|emission_co2e_co2_inen_mining|emission_co2e_co2_inen_other_product_manufacturing|emission_co2e_co2_inen_paper|emission_co2e_co2_inen_plastic|emission_co2e_co2_inen_recycled_glass|emission_co2e_co2_inen_recycled_metals|emission_co2e_co2_inen_recycled_paper|emission_co2e_co2_inen_recycled_plastic|emission_co2e_co2_inen_recycled_rubber_and_leather|emission_co2e_co2_inen_recycled_textiles|emission_co2e_co2_inen_recycled_wood|emission_co2e_co2_inen_rubber_and_leather|emission_co2e_co2_inen_textiles | D34: :math:\text{CO}_2 Emissions from Industrial Energy|NemoMod :math:\text{CO}_2 Emissions from Fuel Processing and Refinement | E34: 1 | F34: MMT | G34: co2e | H34: CO2FFC | I34: Emissions (MMTCO2 Eq.) | J34: Industrial | K34: Coal|Natural Gas|Other|Petroleum | L34: 15|17|18|16 | N34: 108.04245 | O34: 105.17365 | P34: 111.65306 | Q34: 113.17479 | R34: 115.58416 | S34: 115.08509 | T34: 119.53251 | U34: 126.84874 | V34: 112.58668 | W34: 111.82999 | X34: 118.6388 | Y34: 105.83181 | Z34: 109.57081 | AA34: 108.24071 | AB34: 115.11097 | AC34: 108.92128 | AD34: 118.80916 | AE34: 115.88473 | AF34: 112.21489 | AG34: 104.91424 | AH34: 111.62635 | AI34: 112.11835 | AJ34: 112.15582 | AK34: 109.30861 | AL34: 107.11733 | AM34: 106.77188 | AN34: 111.83272 | AO34: 116.67317 | AP34: 121.08807 | AQ34: 122.62423 | AR34: 117.36393 | AS34: 116.70887 | AT34: 0 | AU34: 0 | AV34: 0 | AW34: 0 | AZ34: 1 | BA34: =+AZ34*AS34 -> 116.70887
A35: Energy Technology|Industrial Energy | B35: ch4 | C35: emission_co2e_ch4_entc_processing_and_refinement_fp_ammonia_production|emission_co2e_ch4_entc_processing_and_refinement_fp_hydrogen_electrolysis|emission_co2e_ch4_entc_processing_and_refinement_fp_hydrogen_gasification|emission_co2e_ch4_entc_processing_and_refinement_fp_hydrogen_reformation|emission_co2e_ch4_entc_processing_and_refinement_fp_hydrogen_reformation_ccs emission_co2e_ch4_inen_agriculture_and_livestock|emission_co2e_ch4_inen_cement|emission_co2e_ch4_inen_chemicals|emission_co2e_ch4_inen_electronics|emission_co2e_ch4_inen_glass|emission_co2e_ch4_inen_lime_and_carbonite|emission_co2e_ch4_inen_metals|emission_co2e_ch4_inen_mining|emission_co2e_ch4_inen_other_product_manufacturing|emission_co2e_ch4_inen_paper|emission_co2e_ch4_inen_plastic|emission_co2e_ch4_inen_recycled_glass|emission_co2e_ch4_inen_recycled_metals|emission_co2e_ch4_inen_recycled_paper|emission_co2e_ch4_inen_recycled_plastic|emission_co2e_ch4_inen_recycled_rubber_and_leather|emission_co2e_ch4_inen_recycled_textiles|emission_co2e_ch4_inen_recycled_wood|emission_co2e_ch4_inen_rubber_and_leather|emission_co2e_ch4_inen_textiles | D35: :math:\text{CH}_4 Emissions from Industrial Energy|NemoMod :math:\text{CH}_4 Emissions from Fuel Processing and Refinement | E35: 1 | F35: MMT | G35: co2e | H35: Stationary | I35: Emissions (MMTCO2 Eq.) | K35: CH4 | L35: 12 | N35: 0.15368455 | O35: 0.15102397 | P35: 0.15961178 | Q35: 0.15998004 | R35: 0.17092587 | S35: 0.17332045 | T35: 0.17627557 | U35: 0.18089714 | V35: 0.16775613 | W35: 0.16887171 | X35: 0.17470272 | Y35: 0.16337602 | Z35: 0.17000796 | AA35: 0.17357424 | AB35: 0.20797206 | AC35: 0.17950135 | AD35: 0.1846716 | AE35: 0.17601399 | AF35: 0.13244267 | AG35: 0.12648244 | AH35: 0.13849834 | AI35: 0.1391536 | AJ35: 0.14236598 | AK35: 0.14769697 | AL35: 0.16207444 | AM35: 0.15098911 | AN35: 0.16885882 | AO35: 0.16057328 | AP35: 0.15875683 | AQ35: 0.15075496 | AR35: 0.14467757 | AS35: 0.14207225 | AT35: 0 | AU35: 0 | AV35: 0 | AW35: 0 | AZ35: 1 | BA35: =+AZ35*AS35 -> 0.14207225
A36: Energy Technology|Industrial Energy | B36: n2o | C36: emission_co2e_n2o_entc_processing_and_refinement_fp_ammonia_production|emission_co2e_n2o_entc_processing_and_refinement_fp_hydrogen_electrolysis|emission_co2e_n2o_entc_processing_and_refinement_fp_hydrogen_gasification|emission_co2e_n2o_entc_processing_and_refinement_fp_hydrogen_reformation|emission_co2e_n2o_entc_processing_and_refinement_fp_hydrogen_reformation_ccs|emission_co2e_n2o_inen_agriculture_and_livestock|emission_co2e_n2o_inen_cement|emission_co2e_n2o_inen_chemicals|emission_co2e_n2o_inen_electronics|emission_co2e_n2o_inen_glass|emission_co2e_n2o_inen_lime_and_carbonite|emission_co2e_n2o_inen_metals|emission_co2e_n2o_inen_mining|emission_co2e_n2o_inen_other_product_manufacturing|emission_co2e_n2o_inen_paper|emission_co2e_n2o_inen_plastic|emission_co2e_n2o_inen_recycled_glass|emission_co2e_n2o_inen_recycled_metals|emission_co2e_n2o_inen_recycled_paper|emission_co2e_n2o_inen_recycled_plastic|emission_co2e_n2o_inen_recycled_rubber_and_leather|emission_co2e_n2o_inen_recycled_textiles|emission_co2e_n2o_inen_recycled_wood|emission_co2e_n2o_inen_rubber_and_leather|emission_co2e_n2o_inen_textiles | D36: :math:\text{N}_2\text{O} Emissions from Industrial Energy|NemoMod :math:\text{N}_2\text{O} Emissions from Fuel Processing and Refinement | E36: 1 | F36: MMT | G36: co2e | H36: Stationary | I36: Emissions (MMTCO2 Eq.) | K36: N2O | L36: 11 | N36: 0.20585407 | O36: 0.20149104 | P36: 0.21525445 | Q36: 0.21609989 | R36: 0.23174922 | S36: 0.23376084 | T36: 0.24038892 | U36: 0.24461985 | V36: 0.22679043 | W36: 0.2294907 | X36: 0.23921255 | Y36: 0.22603404 | Z36: 0.23553974 | AA36: 0.24057823 | AB36: 0.28545816 | AC36: 0.24783548 | AD36: 0.25681593 | AE36: 0.23987224 | AF36: 0.18238956 | AG36: 0.17516016 | AH36: 0.19158521 | AI36: 0.19267614 | AJ36: 0.19736298 | AK36: 0.20243499 | AL36: 0.21748047 | AM36: 0.20421348 | AN36: 0.2277977 | AO36: 0.21740113 | AP36: 0.21428502 | AQ36: 0.20398418 | AR36: 0.19435855 | AS36: 0.1916771 | AT36: 0 | AU36: 0 | AV36: 0 | AW36: 0 | AZ36: 1 | BA36: =+AZ36*AS36 -> 0.1916771
A37: Forest | B37: co2 | C37: emission_co2e_co2_frst_harvested_wood_products | D37: :math:\text{CO}_2 Emissions from Harvested Wood Products | E37: 1 | F37: MMT | G37: co2e | H37: Forest Management | I37: Emissions (MMTCO2E) | J37: Forest Land Remaining Forest Land | K37: Total wood products and landfills | L37: 27 | N37: -10.860612 | O37: -10.860612 | P37: -10.860612 | Q37: -10.155088 | R37: -10.155088 | S37: -10.155088 | T37: -10.155088 | U37: -10.155088 | V37: -10.155088 | W37: -10.155088 | X37: -10.155088 | Y37: -10.155088 | Z37: -10.155088 | AA37: -10.155088 | AB37: -10.155088 | AC37: -10.155088 | AD37: -10.155088 | AE37: -10.155088 | AF37: -10.155088 | AG37: -10.155088 | AH37: -10.155088 | AI37: -10.155088 | AJ37: -10.155088 | AK37: -10.155088 | AL37: -10.155088 | AM37: -10.155088 | AN37: -10.155088 | AO37: -10.155088 | AP37: -10.155088 | AQ37: -10.155088 | AR37: -10.155088 | AS37: -10.155088 | AT37: 0 | AU37: 0 | AV37: 0 | AW37: 0 | AZ37: 1 | BA37: =+AZ37*AS37 -> -10.155088 | BC37: =+BA37+BA38+BA42 -> -36.545088
A38: Forest | B38: co2 | C38: emission_co2e_co2_frst_sequestration_mangroves|emission_co2e_co2_frst_sequestration_primary|emission_co2e_co2_frst_sequestration_secondary | D38: :math:\text{CO}_2 Emissions from Forest Biomass Sequestration | E38: 1 | F38: MMT | G38: co2e | H38: Forest Management | I38: Emissions (MMTCO2E) | J38: Forest Land Remaining Forest Land | K38: Aboveground Biomass|Belowground Biomass|Deadwood|Litter | L38: 20|21|22|23 | N38: -17.58 | O38: -17.51 | P38: -17.46 | Q38: -17.39 | R38: -17.34 | S38: -17.28 | T38: -17.22 | U38: -17.15 | V38: -17.09 | W38: -17.51 | X38: -17.94 | Y38: -18.36 | Z38: -18.79 | AA38: -19.22 | AB38: -19.65 | AC38: -20.06 | AD38: -20.48 | AE38: -21.13 | AF38: -21.77 | AG38: -22.42 | AH38: -23.06 | AI38: -23.71 | AJ38: -24.35 | AK38: -24.99 | AL38: -25.64 | AM38: -25.75 | AN38: -25.86 | AO38: -25.97 | AP38: -26.07 | AQ38: -26.18 | AR38: -26.28 | AS38: -26.39 | AT38: 0 | AU38: 0 | AV38: 0 | AW38: 0 | AZ38: 1 | BA38: =+AZ38*AS38 -> -26.39
A39: Forest | B39: ch4 | C39: emission_co2e_ch4_frst_methane_mangroves | D39: :math:\text{CH}_4 Emissions from Forests | E39: 0 | F39: NA | G39: NA | H39: NA | I39: NA | J39: NA | K39: NA | L39: -1 | BA39: =+AZ39*AS39 -> 0
A40: Forest | B40: ch4 | C40: emission_co2e_ch4_frst_methane_primary | D40: :math:\text{CH}_4 Emissions from Forests | E40: 0 | F40: NA | G40: NA | H40: NA | I40: NA | J40: NA | K40: NA | L40: -1 | BA40: =+AZ40*AS40 -> 0
...

Sheet Equivalence Factor
A1: subsector | B1: gas | C1: variable_field | D1: variables | E1: accounted | F1: sit_units | G1: sit_gas_measure | H1: sit_sheet | I1: sit_sections | J1: sit_subsections | K1: sit_categories | L1: MTCO2e:factor
A2: Agriculture | B2: ch4 | C2: emission_co2e_ch4_agrc_anaerobicdom_rice | D2: :math:\text{CH}_4 Emissions from Manure Management | E2: 1 | F2: MMT | G2: ch4 | H2: Agriculture | I2: Emissions by Gas (MMTCH4 or MMTN2O) | J2: Methane | K2: Rice Cultivation | L2: 28
A3: Agriculture | B3: ch4 | C3: emission_co2e_ch4_agrc_biomass_burning | D3: :math:\text{CH}_4 Emissions from Biomass Burning | E3: 1 | F3: MMT | G3: ch4 | H3: Agriculture | I3: Emissions by Gas (MMTCH4 or MMTN2O) | J3: Methane | K3: Burning of Agricultural Crop Waste | L3: 28
A4: Agriculture | B4: n2o | C4: emission_co2e_n2o_agrc_biomass_burning | D4: :math:\text{N}_2\text{O} Emissions from Biomass Burning | E4: 1 | F4: MMT | G4: n2o | H4: Agriculture | I4: Emissions by Gas (MMTCH4 or MMTN2O) | J4: Nitrous Oxide | K4: Burning of Agricultural Crop Waste | L4: 265
A5: Agriculture | B5: co2 | C5: emission_co2e_co2_agrc_biomass_bevs_and_spices | D5: :math:\text{CO}_2 Emissions from Biomass Carbon Stock Changes | E5: 0 | F5: NA | G5: NA | H5: NA | I5: NA | J5: NA | K5: NA
A6: Agriculture | B6: co2 | C6: emission_co2e_co2_agrc_biomass_fruits | D6: :math:\text{CO}_2 Emissions from Biomass Carbon Stock Changes | E6: 0 | F6: NA | G6: NA | H6: NA | I6: NA | J6: NA | K6: NA
A7: Agriculture | B7: co2 | C7: emission_co2e_co2_agrc_biomass_nuts | D7: :math:\text{CO}_2 Emissions from Biomass Carbon Stock Changes | E7: 0 | F7: NA | G7: NA | H7: NA | I7: NA | J7: NA | K7: NA
A8: Agriculture | B8: co2 | C8: emission_co2e_co2_agrc_biomass_other_woody_perennial | D8: :math:\text{CO}_2 Emissions from Biomass Carbon Stock Changes | E8: 0 | F8: NA | G8: NA | H8: NA | I8: NA | J8: NA | K8: NA
A9: Agriculture | B9: co2 | C9: emission_co2e_co2_agrc_soil_carbon_organic_soils | D9: :math:\text{CO}_2 Emissions from Soil Carbon in Organic Soils | E9: 0 | F9: NA | G9: NA | H9: NA | I9: NA | J9: NA | K9: NA
A10: Agriculture|Soil Management | B10: n2o | C10: emission_co2e_n2o_agrc_crop_residues | D10: :math:\text{N}_2\text{O} Emissions from Crop Residues | E10: 1 | F10: MT | G10: n2o | H10: Agriculture | I10: Nitrous Oxide Emissions from Agricultural Soil Management (Metric Tons N2O) | J10: Direct | K10: Crop Residues | L10: 0.000265
A11: Carbon Capture and Sequestration | B11: ch4 | C11: emission_co2e_ch4_ccsq_direct_air_capture | D11: :math:\text{CH}_4 Emissions from CCSQ | E11: 0 | F11: NA | G11: NA | H11: NA | I11: NA | J11: NA | K11: NA
A12: Carbon Capture and Sequestration | B12: co2 | C12: emission_co2e_co2_ccsq_direct_air_capture | D12: :math:\text{CO}_2 Emissions from CCSQ | E12: 0 | F12: NA | G12: NA | H12: NA | I12: NA | J12: NA | K12: NA
A13: Carbon Capture and Sequestration | B13: n2o | C13: emission_co2e_n2o_ccsq_direct_air_capture | D13: :math:\text{N}_2\text{O} Emissions from CCSQ | E13: 0 | F13: NA | G13: NA | H13: NA | I13: NA | J13: NA | K13: NA
A14: Energy Technology | B14: co2 | C14: emission_co2e_co2_entc_generation_pp_biogas|emission_co2e_co2_entc_generation_pp_biomass|emission_co2e_co2_entc_generation_pp_geothermal|emission_co2e_co2_entc_generation_pp_hydropower|emission_co2e_co2_entc_generation_pp_nuclear|emission_co2e_co2_entc_generation_pp_ocean|emission_co2e_co2_entc_generation_pp_solar|emission_co2e_co2_entc_generation_pp_waste_incineration|emission_co2e_co2_entc_generation_pp_wind | D14: NemoMod :math:\text{CO}_2 Emissions from Electricity Generation | E14: 1 | F14: MMT | G14: co2e | H14: CO2FFC | I14: Emissions (MMTCO2 Eq.) | J14: Electric Utilities | K14: Other | L14: 1
A15: Energy Technology | B15: co2 | C15: emission_co2e_co2_entc_generation_pp_coal|emission_co2e_co2_entc_generation_pp_coal_ccs | D15: NemoMod :math:\text{CO}_2 Emissions from Electricity Generation | E15: 1 | F15: MMT | G15: co2e | H15: CO2FFC | I15: Emissions (MMTCO2 Eq.) | J15: Electric Utilities | K15: Coal | L15: 1
A16: Energy Technology | B16: co2 | C16: emission_co2e_co2_entc_generation_pp_gas|emission_co2e_co2_entc_generation_pp_gas_ccs | D16: NemoMod :math:\text{CO}_2 Emissions from Electricity Generation | E16: 1 | F16: MMT | G16: co2e | H16: CO2FFC | I16: Emissions (MMTCO2 Eq.) | J16: Electric Utilities | K16: Natural Gas | L16: 1
A17: Energy Technology | B17: co2 | C17: emission_co2e_co2_entc_generation_pp_oil | D17: NemoMod :math:\text{CO}_2 Emissions from Electricity Generation | E17: 1 | F17: MMT | G17: co2e | H17: CO2FFC | I17: Emissions (MMTCO2 Eq.) | J17: Electric Utilities | K17: Petroleum | L17: 1
A18: Energy Technology | B18: co2 | C18: emission_co2e_co2_entc_processing_and_refinement_fp_ammonia_production | D18: NemoMod :math:\text{CO}_2 Emissions from Fuel Processing and Refinement | E18: 1 | F18: MT | G18: co2e | H18: IP | I18: Emissions (MTCO2 Eq.) | J18: Carbon Dioxide Emissions | K18: Aluminum Production, CO2 | L18: 1e-06
A19: Energy Technology | B19: co2 | C19: emission_co2e_co2_entc_fuel_mining_and_extraction_me_coal | D19: NemoMod :math:\text{CO}_2 Emissions from Fuel Mining and Extraction | E19: 0 | F19: NA | G19: NA | H19: NA | I19: NA | J19: NA | K19: NA
A20: Energy Technology | B20: co2 | C20: emission_co2e_co2_entc_fuel_mining_and_extraction_me_crude | D20: NemoMod :math:\text{CO}_2 Emissions from Fuel Mining and Extraction | E20: 0 | F20: NA | G20: NA | H20: NA | I20: NA | J20: NA | K20: NA
A21: Energy Technology | B21: co2 | C21: emission_co2e_co2_entc_processing_and_refinement_fp_natural_gas | D21: NemoMod :math:\text{CO}_2 Emissions from Fuel Processing and Refinement | E21: 0 | F21: NA | G21: NA | H21: NA | I21: NA | J21: NA | K21: NA
A22: Energy Technology | B22: co2 | C22: emission_co2e_co2_entc_processing_and_refinement_fp_petroleum_refinement | D22: NemoMod :math:\text{CO}_2 Emissions from Fuel Processing and Refinement | E22: 0 | F22: NA | G22: NA | H22: NA | I22: NA | J22: NA | K22: NA
A23: Energy Technology | B23: n2o | C23: emission_co2e_n2o_entc_fuel_mining_and_extraction_me_coal | D23: NemoMod :math:\text{N}_2\text{O} Emissions from Fuel Mining and Extraction | E23: 0 | F23: NA | G23: NA | H23: NA | I23: NA | J23: NA | K23: NA
A24: Energy Technology | B24: n2o | C24: emission_co2e_n2o_entc_fuel_mining_and_extraction_me_crude | D24: NemoMod :math:\text{N}_2\text{O} Emissions from Fuel Mining and Extraction | E24: 0 | F24: NA | G24: NA | H24: NA | I24: NA | J24: NA | K24: NA
A25: Energy Technology | B25: n2o | C25: emission_co2e_n2o_entc_fuel_mining_and_extraction_me_natural_gas | D25: NemoMod :math:\text{N}_2\text{O} Emissions from Fuel Mining and Extraction | E25: 0 | F25: NA | G25: NA | H25: NA | I25: NA | J25: NA | K25: NA
A26: Energy Technology | B26: n2o | C26: emission_co2e_n2o_entc_processing_and_refinement_fp_natural_gas | D26: NemoMod :math:\text{N}_2\text{O} Emissions from Fuel Processing and Refinement | E26: 0 | F26: NA | G26: NA | H26: NA | I26: NA | J26: NA | K26: NA
A27: Energy Technology | B27: n2o | C27: emission_co2e_n2o_entc_processing_and_refinement_fp_petroleum_refinement | D27: NemoMod :math:\text{N}_2\text{O} Emissions from Fuel Processing and Refinement | E27: 0 | F27: NA | G27: NA | H27: NA | I27: NA | J27: NA | K27: NA
A28: Energy Technology | B28: ch4 | C28: emission_co2e_ch4_entc_generation_pp_biogas|emission_co2e_ch4_entc_generation_pp_biomass|emission_co2e_ch4_entc_generation_pp_coal|emission_co2e_ch4_entc_generation_pp_coal_ccs|emission_co2e_ch4_entc_generation_pp_gas|emission_co2e_ch4_entc_generation_pp_gas_ccs|emission_co2e_ch4_entc_generation_pp_geothermal|emission_co2e_ch4_entc_generation_pp_hydropower|emission_co2e_ch4_entc_generation_pp_nuclear|emission_co2e_ch4_entc_generation_pp_ocean|emission_co2e_ch4_entc_generation_pp_oil|emission_co2e_ch4_entc_generation_pp_solar|emission_co2e_ch4_entc_generation_pp_waste_incineration|emission_co2e_ch4_entc_generation_pp_wind | D28: NemoMod :math:\text{CH}_4 Emissions from Electricity Generation | E28: 1 | F28: MMT | G28: co2e | H28: Stationary | I28: Emissions (MMTCO2 Eq.) | J28: Electric Utilities | K28: CH4 | L28: 1
A29: Energy Technology | B29: n2o | C29: emission_co2e_n2o_entc_generation_pp_biogas|emission_co2e_n2o_entc_generation_pp_biomass|emission_co2e_n2o_entc_generation_pp_coal|emission_co2e_n2o_entc_generation_pp_coal_ccs|emission_co2e_n2o_entc_generation_pp_gas|emission_co2e_n2o_entc_generation_pp_gas_ccs|emission_co2e_n2o_entc_generation_pp_geothermal|emission_co2e_n2o_entc_generation_pp_hydropower|emission_co2e_n2o_entc_generation_pp_nuclear|emission_co2e_n2o_entc_generation_pp_ocean|emission_co2e_n2o_entc_generation_pp_oil|emission_co2e_n2o_entc_generation_pp_solar|emission_co2e_n2o_entc_generation_pp_waste_incineration|emission_co2e_n2o_entc_generation_pp_wind | D29: NemoMod :math:\text{N}_2\text{O} Emissions from Electricity Generation | E29: 1 | F29: MMT | G29: co2e | H29: Stationary | I29: Emissions (MMTCO2 Eq.) | J29: Electric Utilities | K29: N2O | L29: 1
A30: Energy Technology|Fugitive Emissions | B30: ch4 | C30: emission_co2e_ch4_entc_fuel_mining_and_extraction_me_coal|emission_co2e_ch4_fgtv_fuel_coal | D30: :math:\text{CH}_4 Fugitive Emissions|NemoMod :math:\text{CH}_4 Emissions from Fuel Mining and Extraction | E30: 1 | F30: MT | G30: ch4 | H30: Coal | I30: Emissions (MTCO2E) | J30: Coal Mining | L30: 2.8e-05
A31: Energy Technology|Fugitive Emissions | B31: ch4 | C31: emission_co2e_ch4_entc_fuel_mining_and_extraction_me_crude|emission_co2e_ch4_entc_processing_and_refinement_fp_petroleum_refinement|emission_co2e_ch4_fgtv_fuel_oil | D31: :math:\text{CH}_4 Fugitive Emissions|NemoMod :math:\text{CH}_4 Emissions from Fuel Mining and Extraction|NemoMod :math:\text{CH}_4 Emissions from Fuel Processing and Refinement | E31: 1 | F31: MT | G31: ch4 | H31: Gas and Oil | I31: Emissions (MMTCO2 Eq.) | J31: Oil | L31: 2.8e-05
A32: Energy Technology|Fugitive Emissions | B32: ch4 | C32: emission_co2e_ch4_entc_fuel_mining_and_extraction_me_natural_gas|emission_co2e_ch4_entc_processing_and_refinement_fp_natural_gas|emission_co2e_ch4_fgtv_fuel_natural_gas | D32: :math:\text{CH}_4 Fugitive Emissions|NemoMod :math:\text{CH}_4 Emissions from Fuel Mining and Extraction|NemoMod :math:\text{CH}_4 Emissions from Fuel Processing and Refinement | E32: 1 | F32: MT | G32: ch4 | H32: Gas and Oil | I32: Emissions by Gas (MTCH4) | J32: Natural Gas | L32: 2.8e-05
A33: Energy Technology|Fugitive Emissions | B33: co2 | C33: emission_co2e_co2_entc_fuel_mining_and_extraction_me_natural_gas|emission_co2e_co2_fgtv_fuel_natural_gas | D33: :math:\text{CO}_2 Fugitive Emissions|NemoMod :math:\text{CO}_2 Emissions from Fuel Mining and Extraction | E33: 1 | F33: MMT | G33: co2e | H33: Gas and Oil | I33: Emissions (MMTCO2 Eq.) | J33: Natural Gas | L33: 1
A34: Energy Technology|Industrial Energy | B34: co2 | C34: emission_co2e_co2_entc_processing_and_refinement_fp_hydrogen_electrolysis|emission_co2e_co2_entc_processing_and_refinement_fp_hydrogen_gasification|emission_co2e_co2_entc_processing_and_refinement_fp_hydrogen_reformation|emission_co2e_co2_entc_processing_and_refinement_fp_hydrogen_reformation_ccs|emission_co2e_co2_inen_agriculture_and_livestock|emission_co2e_co2_inen_cement|emission_co2e_co2_inen_chemicals|emission_co2e_co2_inen_electronics|emission_co2e_co2_inen_glass|emission_co2e_co2_inen_lime_and_carbonite|emission_co2e_co2_inen_metals|emission_co2e_co2_inen_mining|emission_co2e_co2_inen_other_product_manufacturing|emission_co2e_co2_inen_paper|emission_co2e_co2_inen_plastic|emission_co2e_co2_inen_recycled_glass|emission_co2e_co2_inen_recycled_metals|emission_co2e_co2_inen_recycled_paper|emission_co2e_co2_inen_recycled_plastic|emission_co2e_co2_inen_recycled_rubber_and_leather|emission_co2e_co2_inen_recycled_textiles|emission_co2e_co2_inen_recycled_wood|emission_co2e_co2_inen_rubber_and_leather|emission_co2e_co2_inen_textiles | D34: :math:\text{CO}_2 Emissions from Industrial Energy|NemoMod :math:\text{CO}_2 Emissions from Fuel Processing and Refinement | E34: 1 | F34: MMT | G34: co2e | H34: CO2FFC | I34: Emissions (MMTCO2 Eq.) | J34: Industrial | K34: Coal|Natural Gas|Other|Petroleum | L34: 1
A35: Energy Technology|Industrial Energy | B35: ch4 | C35: emission_co2e_ch4_entc_processing_and_refinement_fp_ammonia_production|emission_co2e_ch4_entc_processing_and_refinement_fp_hydrogen_electrolysis|emission_co2e_ch4_entc_processing_and_refinement_fp_hydrogen_gasification|emission_co2e_ch4_entc_processing_and_refinement_fp_hydrogen_reformation|emission_co2e_ch4_entc_processing_and_refinement_fp_hydrogen_reformation_ccs emission_co2e_ch4_inen_agriculture_and_livestock|emission_co2e_ch4_inen_cement|emission_co2e_ch4_inen_chemicals|emission_co2e_ch4_inen_electronics|emission_co2e_ch4_inen_glass|emission_co2e_ch4_inen_lime_and_carbonite|emission_co2e_ch4_inen_metals|emission_co2e_ch4_inen_mining|emission_co2e_ch4_inen_other_product_manufacturing|emission_co2e_ch4_inen_paper|emission_co2e_ch4_inen_plastic|emission_co2e_ch4_inen_recycled_glass|emission_co2e_ch4_inen_recycled_metals|emission_co2e_ch4_inen_recycled_paper|emission_co2e_ch4_inen_recycled_plastic|emission_co2e_ch4_inen_recycled_rubber_and_leather|emission_co2e_ch4_inen_recycled_textiles|emission_co2e_ch4_inen_recycled_wood|emission_co2e_ch4_inen_rubber_and_leather|emission_co2e_ch4_inen_textiles | D35: :math:\text{CH}_4 Emissions from Industrial Energy|NemoMod :math:\text{CH}_4 Emissions from Fuel Processing and Refinement | E35: 1 | F35: MMT | G35: co2e | H35: Stationary | I35: Emissions (MMTCO2 Eq.) | K35: CH4 | L35: 1
A36: Energy Technology|Industrial Energy | B36: n2o | C36: emission_co2e_n2o_entc_processing_and_refinement_fp_ammonia_production|emission_co2e_n2o_entc_processing_and_refinement_fp_hydrogen_electrolysis|emission_co2e_n2o_entc_processing_and_refinement_fp_hydrogen_gasification|emission_co2e_n2o_entc_processing_and_refinement_fp_hydrogen_reformation|emission_co2e_n2o_entc_processing_and_refinement_fp_hydrogen_reformation_ccs|emission_co2e_n2o_inen_agriculture_and_livestock|emission_co2e_n2o_inen_cement|emission_co2e_n2o_inen_chemicals|emission_co2e_n2o_inen_electronics|emission_co2e_n2o_inen_glass|emission_co2e_n2o_inen_lime_and_carbonite|emission_co2e_n2o_inen_metals|emission_co2e_n2o_inen_mining|emission_co2e_n2o_inen_other_product_manufacturing|emission_co2e_n2o_inen_paper|emission_co2e_n2o_inen_plastic|emission_co2e_n2o_inen_recycled_glass|emission_co2e_n2o_inen_recycled_metals|emission_co2e_n2o_inen_recycled_paper|emission_co2e_n2o_inen_recycled_plastic|emission_co2e_n2o_inen_recycled_rubber_and_leather|emission_co2e_n2o_inen_recycled_textiles|emission_co2e_n2o_inen_recycled_wood|emission_co2e_n2o_inen_rubber_and_leather|emission_co2e_n2o_inen_textiles | D36: :math:\text{N}_2\text{O} Emissions from Industrial Energy|NemoMod :math:\text{N}_2\text{O} Emissions from Fuel Processing and Refinement | E36: 1 | F36: MMT | G36: co2e | H36: Stationary | I36: Emissions (MMTCO2 Eq.) | K36: N2O | L36: 1
A37: Forest | B37: co2 | C37: emission_co2e_co2_frst_harvested_wood_products | D37: :math:\text{CO}_2 Emissions from Harvested Wood Products | E37: 1 | F37: MMT | G37: co2e | H37: Forest Management | I37: Emissions (MMTCO2E) | J37: Forest Land Remaining Forest Land | K37: Total wood products and landfills | L37: 1
A38: Forest | B38: co2 | C38: emission_co2e_co2_frst_sequestration_mangroves|emission_co2e_co2_frst_sequestration_primary|emission_co2e_co2_frst_sequestration_secondary | D38: :math:\text{CO}_2 Emissions from Forest Biomass Sequestration | E38: 1 | F38: MMT | G38: co2e | H38: Forest Management | I38: Emissions (MMTCO2E) | J38: Forest Land Remaining Forest Land | K38: Aboveground Biomass|Belowground Biomass|Deadwood|Litter | L38: 1
A39: Forest | B39: ch4 | C39: emission_co2e_ch4_frst_methane_mangroves | D39: :math:\text{CH}_4 Emissions from Forests | E39: 0 | F39: NA | G39: NA | H39: NA | I39: NA | J39: NA | K39: NA
A40: Forest | B40: ch4 | C40: emission_co2e_ch4_frst_methane_primary | D40: :math:\text{CH}_4 Emissions from Forests | E40: 0 | F40: NA | G40: NA | H40: NA | I40: NA | J40: NA | K40: NA
...

Sheet CO2evalues
A1: subsector_long | B1: Subsector | C1: gas | D1: variable_field | E1: variables | F1: accounted | G1: sit_units | H1: sit_gas_measure | I1: sit_sheet | J1: sit_sections | K1: sit_subsections | L1: sit_categories | M1: sit_rows | N1: notes | O1: 1990 | P1: 1991 | Q1: 1992 | R1: 1993 | S1: 1994 | T1: 1995 | U1: 1996 | V1: 1997 | W1: 1998 | X1: 1999 | Y1: 2000 | Z1: 2001 | AA1: 2002 | AB1: 2003 | AC1: 2004 | AD1: 2005 | AE1: 2006 | AF1: 2007 | AG1: 2008 | AH1: 2009 | AI1: 2010 | AJ1: 2011 | AK1: 2012 | AL1: 2013 | AM1: 2014 | AN1: 2015 | AO1: 2016 | AP1: 2017 | AQ1: 2018 | AR1: 2019 | AS1: 2020 | AT1: 2021
A2: Agriculture | B2: agrc | C2: ch4 | D2: emission_co2e_ch4_agrc_anaerobicdom_rice | E2: :math:\text{CH}_4 Emissions from Manure Management | F2: 1 | G2: MMT | H2: ch4 | I2: Agriculture | J2: Emissions by Gas (MMTCH4 or MMTN2O) | K2: Methane | L2: Rice Cultivation | M2: 35 | O2: =+sum_sheet!N2*'Equivalence Factor'!$L2 -> 3.0056415 | P2: =+sum_sheet!O2*'Equivalence Factor'!$L2 -> 2.8126187 | Q2: =+sum_sheet!P2*'Equivalence Factor'!$L2 -> 3.4192619 | R2: =+sum_sheet!Q2*'Equivalence Factor'!$L2 -> 2.9229175 | S2: =+sum_sheet!R2*'Equivalence Factor'!$L2 -> 3.4192619 | T2: =+sum_sheet!S2*'Equivalence Factor'!$L2 -> 3.143515 | U2: =+sum_sheet!T2*'Equivalence Factor'!$L2 -> 2.9394623 | V2: =+sum_sheet!U2*'Equivalence Factor'!$L2 -> 3.2152092 | ... AT2: =+sum_sheet!AS2*'Equivalence Factor'!$L2 -> 2.2776697
A3: Agriculture | B3: agrc | C3: ch4 | D3: emission_co2e_ch4_agrc_biomass_burning | E3: :math:\text{CH}_4 Emissions from Biomass Burning | F3: 1 | G3: MMT | H3: ch4 | I3: Agriculture | J3: Emissions by Gas (MMTCH4 or MMTN2O) | K3: Methane | L3: Burning of Agricultural Crop Waste | M3: 36 | O3: =+sum_sheet!N3*'Equivalence Factor'!$L3 -> 0.043555414 | P3: =+sum_sheet!O3*'Equivalence Factor'!$L3 -> 0.058282724 | Q3: =+sum_sheet!P3*'Equivalence Factor'!$L3 -> 0.067383842 | R3: =+sum_sheet!Q3*'Equivalence Factor'!$L3 -> 0.066880951 | S3: =+sum_sheet!R3*'Equivalence Factor'!$L3 -> 0.070056814 | T3: =+sum_sheet!S3*'Equivalence Factor'!$L3 -> 0.076948846 | U3: =+sum_sheet!T3*'Equivalence Factor'!$L3 -> 0.078818949 | V3: =+sum_sheet!U3*'Equivalence Factor'!$L3 -> 0.08726418 | ... AT3: =+sum_sheet!AS3*'Equivalence Factor'!$L3 -> 0.10730407
A4: Agriculture | B4: agrc | C4: n2o | D4: emission_co2e_n2o_agrc_biomass_burning | E4: :math:\text{N}_2\text{O} Emissions from Biomass Burning | F4: 1 | G4: MMT | H4: n2o | I4: Agriculture | J4: Emissions by Gas (MMTCH4 or MMTN2O) | K4: Nitrous Oxide | L4: Burning of Agricultural Crop Waste | M4: 40 | O4: =+sum_sheet!N4*'Equivalence Factor'!$L4 -> 0.0071414728 | P4: =+sum_sheet!O4*'Equivalence Factor'!$L4 -> 0.0090019783 | Q4: =+sum_sheet!P4*'Equivalence Factor'!$L4 -> 0.01046043 | R4: =+sum_sheet!Q4*'Equivalence Factor'!$L4 -> 0.010225113 | S4: =+sum_sheet!R4*'Equivalence Factor'!$L4 -> 0.010746983 | T4: =+sum_sheet!S4*'Equivalence Factor'!$L4 -> 0.011725919 | U4: =+sum_sheet!T4*'Equivalence Factor'!$L4 -> 0.01211506 | V4: =+sum_sheet!U4*'Equivalence Factor'!$L4 -> 0.013338149 | ... AT4: =+sum_sheet!AS4*'Equivalence Factor'!$L4 -> 0.016239825
A5: Agriculture | B5: agrc | C5: co2 | D5: emission_co2e_co2_agrc_biomass_bevs_and_spices | E5: :math:\text{CO}_2 Emissions from Biomass Carbon Stock Changes | F5: 0 | G5: NA | H5: NA | I5: NA | J5: NA | K5: NA | L5: NA | M5: -1 | O5: =+sum_sheet!N5*'Equivalence Factor'!$L5 -> 0 | P5: =+sum_sheet!O5*'Equivalence Factor'!$L5 -> 0 | Q5: =+sum_sheet!P5*'Equivalence Factor'!$L5 -> 0 | R5: =+sum_sheet!Q5*'Equivalence Factor'!$L5 -> 0 | S5: =+sum_sheet!R5*'Equivalence Factor'!$L5 -> 0 | T5: =+sum_sheet!S5*'Equivalence Factor'!$L5 -> 0 | U5: =+sum_sheet!T5*'Equivalence Factor'!$L5 -> 0 | V5: =+sum_sheet!U5*'Equivalence Factor'!$L5 -> 0 | ... AT5: =+sum_sheet!AS5*'Equivalence Factor'!$L5 -> 0
A6: Agriculture | B6: agrc | C6: co2 | D6: emission_co2e_co2_agrc_biomass_fruits | E6: :math:\text{CO}_2 Emissions from Biomass Carbon Stock Changes | F6: 0 | G6: NA | H6: NA | I6: NA | J6: NA | K6: NA | L6: NA | M6: -1 | O6: =+sum_sheet!N6*'Equivalence Factor'!$L6 -> 0 | P6: =+sum_sheet!O6*'Equivalence Factor'!$L6 -> 0 | Q6: =+sum_sheet!P6*'Equivalence Factor'!$L6 -> 0 | R6: =+sum_sheet!Q6*'Equivalence Factor'!$L6 -> 0 | S6: =+sum_sheet!R6*'Equivalence Factor'!$L6 -> 0 | T6: =+sum_sheet!S6*'Equivalence Factor'!$L6 -> 0 | U6: =+sum_sheet!T6*'Equivalence Factor'!$L6 -> 0 | V6: =+sum_sheet!U6*'Equivalence Factor'!$L6 -> 0 | ... AT6: =+sum_sheet!AS6*'Equivalence Factor'!$L6 -> 0
A7: Agriculture | B7: agrc | C7: co2 | D7: emission_co2e_co2_agrc_biomass_nuts | E7: :math:\text{CO}_2 Emissions from Biomass Carbon Stock Changes | F7: 0 | G7: NA | H7: NA | I7: NA | J7: NA | K7: NA | L7: NA | M7: -1 | O7: =+sum_sheet!N7*'Equivalence Factor'!$L7 -> 0 | P7: =+sum_sheet!O7*'Equivalence Factor'!$L7 -> 0 | Q7: =+sum_sheet!P7*'Equivalence Factor'!$L7 -> 0 | R7: =+sum_sheet!Q7*'Equivalence Factor'!$L7 -> 0 | S7: =+sum_sheet!R7*'Equivalence Factor'!$L7 -> 0 | T7: =+sum_sheet!S7*'Equivalence Factor'!$L7 -> 0 | U7: =+sum_sheet!T7*'Equivalence Factor'!$L7 -> 0 | V7: =+sum_sheet!U7*'Equivalence Factor'!$L7 -> 0 | ... AT7: =+sum_sheet!AS7*'Equivalence Factor'!$L7 -> 0
A8: Agriculture | B8: agrc | C8: co2 | D8: emission_co2e_co2_agrc_biomass_other_woody_perennial | E8: :math:\text{CO}_2 Emissions from Biomass Carbon Stock Changes | F8: 0 | G8: NA | H8: NA | I8: NA | J8: NA | K8: NA | L8: NA | M8: -1 | O8: =+sum_sheet!N8*'Equivalence Factor'!$L8 -> 0 | P8: =+sum_sheet!O8*'Equivalence Factor'!$L8 -> 0 | Q8: =+sum_sheet!P8*'Equivalence Factor'!$L8 -> 0 | R8: =+sum_sheet!Q8*'Equivalence Factor'!$L8 -> 0 | S8: =+sum_sheet!R8*'Equivalence Factor'!$L8 -> 0 | T8: =+sum_sheet!S8*'Equivalence Factor'!$L8 -> 0 | U8: =+sum_sheet!T8*'Equivalence Factor'!$L8 -> 0 | V8: =+sum_sheet!U8*'Equivalence Factor'!$L8 -> 0 | ... AT8: =+sum_sheet!AS8*'Equivalence Factor'!$L8 -> 0
A9: Agriculture | B9: agrc | C9: co2 | D9: emission_co2e_co2_lndu_drained_organic_soils_croplands|emission_co2e_co2_lndu_drained_organic_soils_pastures | E9: :math:\text{CO}_2 Emissions from Drained Organic Soils | F9: 0 | G9: NA | H9: NA | I9: NA | J9: NA | K9: NA | L9: NA | M9: -1 | O9: =+sum_sheet!N9*'Equivalence Factor'!$L9 -> 0 | P9: =+sum_sheet!O9*'Equivalence Factor'!$L9 -> 0 | Q9: =+sum_sheet!P9*'Equivalence Factor'!$L9 -> 0 | R9: =+sum_sheet!Q9*'Equivalence Factor'!$L9 -> 0 | S9: =+sum_sheet!R9*'Equivalence Factor'!$L9 -> 0 | T9: =+sum_sheet!S9*'Equivalence Factor'!$L9 -> 0 | U9: =+sum_sheet!T9*'Equivalence Factor'!$L9 -> 0 | V9: =+sum_sheet!U9*'Equivalence Factor'!$L9 -> 0 | ... AT9: =+sum_sheet!AS9*'Equivalence Factor'!$L9 -> 0
A10: Agriculture|Soil Management | B10: agrc | C10: n2o | D10: emission_co2e_n2o_agrc_crop_residues | E10: :math:\text{N}_2\text{O} Emissions from Crop Residues | F10: 1 | G10: MT | H10: n2o | I10: Agriculture | J10: Nitrous Oxide Emissions from Agricultural Soil Management (Metric Tons N2O) | K10: Direct | L10: Crop Residues | M10: 46 | O10: =+sum_sheet!N10*'Equivalence Factor'!$L10 -> 0.56726867 | P10: =+sum_sheet!O10*'Equivalence Factor'!$L10 -> 0.42165636 | Q10: =+sum_sheet!P10*'Equivalence Factor'!$L10 -> 0.4812997 | R10: =+sum_sheet!Q10*'Equivalence Factor'!$L10 -> 0.43540415 | S10: =+sum_sheet!R10*'Equivalence Factor'!$L10 -> 0.42734029 | T10: =+sum_sheet!S10*'Equivalence Factor'!$L10 -> 0.3659902 | U10: =+sum_sheet!T10*'Equivalence Factor'!$L10 -> 0.50251276 | V10: =+sum_sheet!U10*'Equivalence Factor'!$L10 -> 0.46381849 | ... AT10: =+sum_sheet!AS10*'Equivalence Factor'!$L10 -> 0.52303501
A11: Carbon Capture and Sequestration | B11: ccsq | C11: ch4 | D11: emission_co2e_ch4_ccsq_direct_air_capture | E11: :math:\text{CH}_4 Emissions from CCSQ | F11: 0 | G11: NA | H11: NA | I11: NA | J11: NA | K11: NA | L11: NA | M11: -1 | O11: =+sum_sheet!N11*'Equivalence Factor'!$L11 -> 0 | P11: =+sum_sheet!O11*'Equivalence Factor'!$L11 -> 0 | Q11: =+sum_sheet!P11*'Equivalence Factor'!$L11 -> 0 | R11: =+sum_sheet!Q11*'Equivalence Factor'!$L11 -> 0 | S11: =+sum_sheet!R11*'Equivalence Factor'!$L11 -> 0 | T11: =+sum_sheet!S11*'Equivalence Factor'!$L11 -> 0 | U11: =+sum_sheet!T11*'Equivalence Factor'!$L11 -> 0 | V11: =+sum_sheet!U11*'Equivalence Factor'!$L11 -> 0 | ... AT11: =+sum_sheet!AS11*'Equivalence Factor'!$L11 -> 0
A12: Carbon Capture and Sequestration | B12: ccsq | C12: co2 | D12: emission_co2e_co2_ccsq_direct_air_capture | E12: :math:\text{CO}_2 Emissions from CCSQ | F12: 0 | G12: NA | H12: NA | I12: NA | J12: NA | K12: NA | L12: NA | M12: -1 | O12: =+sum_sheet!N12*'Equivalence Factor'!$L12 -> 0 | P12: =+sum_sheet!O12*'Equivalence Factor'!$L12 -> 0 | Q12: =+sum_sheet!P12*'Equivalence Factor'!$L12 -> 0 | R12: =+sum_sheet!Q12*'Equivalence Factor'!$L12 -> 0 | S12: =+sum_sheet!R12*'Equivalence Factor'!$L12 -> 0 | T12: =+sum_sheet!S12*'Equivalence Factor'!$L12 -> 0 | U12: =+sum_sheet!T12*'Equivalence Factor'!$L12 -> 0 | V12: =+sum_sheet!U12*'Equivalence Factor'!$L12 -> 0 | ... AT12: =+sum_sheet!AS12*'Equivalence Factor'!$L12 -> 0
A13: Carbon Capture and Sequestration | B13: ccsq | C13: n2o | D13: emission_co2e_n2o_ccsq_direct_air_capture | E13: :math:\text{N}_2\text{O} Emissions from CCSQ | F13: 0 | G13: NA | H13: NA | I13: NA | J13: NA | K13: NA | L13: NA | M13: -1 | O13: =+sum_sheet!N13*'Equivalence Factor'!$L13 -> 0 | P13: =+sum_sheet!O13*'Equivalence Factor'!$L13 -> 0 | Q13: =+sum_sheet!P13*'Equivalence Factor'!$L13 -> 0 | R13: =+sum_sheet!Q13*'Equivalence Factor'!$L13 -> 0 | S13: =+sum_sheet!R13*'Equivalence Factor'!$L13 -> 0 | T13: =+sum_sheet!S13*'Equivalence Factor'!$L13 -> 0 | U13: =+sum_sheet!T13*'Equivalence Factor'!$L13 -> 0 | V13: =+sum_sheet!U13*'Equivalence Factor'!$L13 -> 0 | ... AT13: =+sum_sheet!AS13*'Equivalence Factor'!$L13 -> 0
... A18: Energy Technology | B18: entc | C18: co2 | D18: emission_co2e_co2_entc_processing_and_refinement_fp_ammonia_production | E18: NemoMod :math:\text{CO}_2 Emissions from Fuel Processing and Refinement | F18: 1 | G18: MT | H18: co2e | I18: IP | J18: Emissions (MTCO2 Eq.) | K18: Carbon Dioxide Emissions | L18: Ammonia Production | M18: 11 | O18: =+sum_sheet!N18*'Equivalence Factor'!$L18 -> 6.1184837 | P18: =+sum_sheet!O18*'Equivalence Factor'!$L18 -> 6.1991414 | Q18: =+sum_sheet!P18*'Equivalence Factor'!$L18 -> 6.4792807 | R18: =+sum_sheet!Q18*'Equivalence Factor'!$L18 -> 5.9669368 | S18: =+sum_sheet!R18*'Equivalence Factor'!$L18 -> 6.4276458 | T18: =+sum_sheet!S18*'Equivalence Factor'!$L18 -> 6.0550107 | U18: =+sum_sheet!T18*'Equivalence Factor'!$L18 -> 6.1632771 | V18: =+sum_sheet!U18*'Equivalence Factor'!$L18 -> 5.8758721 | ... AT18: =+sum_sheet!AS18*'Equivalence Factor'!$L18 -> 4.9621202
A19: Energy Technology | B19: entc | C19: ch4 | D19: emission_co2e_ch4_entc_generation_pp_biogas|emission_co2e_ch4_entc_generation_pp_biomass|emission_co2e_ch4_entc_generation_pp_coal|emission_co2e_ch4_entc_generation_pp_coal_ccs|emission_co2e_ch4_entc_generation_pp_gas|emission_co2e_ch4_entc_generation_pp_gas_ccs|emission_co2e_ch4_entc_generation_pp_geothermal|emission_co2e_ch4_entc_generation_pp_hydropower|emission_co2e_ch4_entc_generation_pp_nuclear|emission_co2e_ch4_entc_generation_pp_ocean|emission_co2e_ch4_entc_generation_pp_oil|emission_co2e_ch4_entc_generation_pp_solar|emission_co2e_ch4_entc_generation_pp_waste_incineration|emission_co2e_ch4_entc_generation_pp_wind | E19: NemoMod :math:\text{CH}_4 Emissions from Electricity Generation | F19: 1 | G19: MMT | H19: co2e | I19: Stationary | J19: Emissions (MMTCO2 Eq.) | K19: Electric Utilities | L19: CH4 | M19: 15 | O19: =+sum_sheet!N28*'Equivalence Factor'!$L28 -> 0.013526087 | P19: =+sum_sheet!O28*'Equivalence Factor'!$L28 -> 0.013266356 | Q19: =+sum_sheet!P28*'Equivalence Factor'!$L28 -> 0.014162852 | R19: =+sum_sheet!Q28*'Equivalence Factor'!$L28 -> 0.015973338 | S19: =+sum_sheet!R28*'Equivalence Factor'!$L28 -> 0.016045411 | T19: =+sum_sheet!S28*'Equivalence Factor'!$L28 -> 0.016438266 | U19: =+sum_sheet!T28*'Equivalence Factor'!$L28 -> 0.014494261 | V19: =+sum_sheet!U28*'Equivalence Factor'!$L28 -> 0.0161982 | ... AT19: =+sum_sheet!AS28*'Equivalence Factor'!$L28 -> 0.014862404
